Failure # 1 (occurred at 2023-11-16_22-23-19)
[36mray::SAC.train()[39m (pid=48481, ip=127.0.0.1, actor_id=5b5750e204d47a9f76c41bf201000000, repr=SAC)
  File "/Users/jang-yejun/opt/anaconda3/lib/python3.9/site-packages/ray/tune/trainable/trainable.py", line 342, in train
    raise skipped from exception_cause(skipped)
  File "/Users/jang-yejun/opt/anaconda3/lib/python3.9/site-packages/ray/tune/trainable/trainable.py", line 339, in train
    result = self.step()
  File "/Users/jang-yejun/opt/anaconda3/lib/python3.9/site-packages/ray/rllib/algorithms/algorithm.py", line 853, in step
    results, train_iter_ctx = self._run_one_training_iteration()
  File "/Users/jang-yejun/opt/anaconda3/lib/python3.9/site-packages/ray/rllib/algorithms/algorithm.py", line 2854, in _run_one_training_iteration
    results = self.training_step()
  File "/Users/jang-yejun/opt/anaconda3/lib/python3.9/site-packages/ray/rllib/algorithms/dqn/dqn.py", line 404, in training_step
    new_sample_batch = synchronous_parallel_sample(
  File "/Users/jang-yejun/opt/anaconda3/lib/python3.9/site-packages/ray/rllib/execution/rollout_ops.py", line 85, in synchronous_parallel_sample
    sample_batches = worker_set.foreach_worker(
  File "/Users/jang-yejun/opt/anaconda3/lib/python3.9/site-packages/ray/rllib/evaluation/worker_set.py", line 680, in foreach_worker
    handle_remote_call_result_errors(remote_results, self._ignore_worker_failures)
  File "/Users/jang-yejun/opt/anaconda3/lib/python3.9/site-packages/ray/rllib/evaluation/worker_set.py", line 76, in handle_remote_call_result_errors
    raise r.get()
ray.exceptions.RayTaskError(ValueError): [36mray::RolloutWorker.apply()[39m (pid=48500, ip=127.0.0.1, actor_id=b5dd79b07834b147338242b301000000, repr=<ray.rllib.evaluation.rollout_worker.RolloutWorker object at 0x7f875872df70>)
  File "/Users/jang-yejun/opt/anaconda3/lib/python3.9/site-packages/ray/rllib/utils/actor_manager.py", line 185, in apply
    raise e
  File "/Users/jang-yejun/opt/anaconda3/lib/python3.9/site-packages/ray/rllib/utils/actor_manager.py", line 176, in apply
    return func(self, *args, **kwargs)
  File "/Users/jang-yejun/opt/anaconda3/lib/python3.9/site-packages/ray/rllib/execution/rollout_ops.py", line 86, in <lambda>
    lambda w: w.sample(), local_worker=False, healthy_only=True
  File "/Users/jang-yejun/opt/anaconda3/lib/python3.9/site-packages/ray/rllib/evaluation/rollout_worker.py", line 696, in sample
    batches = [self.input_reader.next()]
  File "/Users/jang-yejun/opt/anaconda3/lib/python3.9/site-packages/ray/rllib/evaluation/sampler.py", line 92, in next
    batches = [self.get_data()]
  File "/Users/jang-yejun/opt/anaconda3/lib/python3.9/site-packages/ray/rllib/evaluation/sampler.py", line 277, in get_data
    item = next(self._env_runner)
  File "/Users/jang-yejun/opt/anaconda3/lib/python3.9/site-packages/ray/rllib/evaluation/env_runner_v2.py", line 344, in run
    outputs = self.step()
  File "/Users/jang-yejun/opt/anaconda3/lib/python3.9/site-packages/ray/rllib/evaluation/env_runner_v2.py", line 370, in step
    active_envs, to_eval, outputs = self._process_observations(
  File "/Users/jang-yejun/opt/anaconda3/lib/python3.9/site-packages/ray/rllib/evaluation/env_runner_v2.py", line 637, in _process_observations
    processed = policy.agent_connectors(acd_list)
  File "/Users/jang-yejun/opt/anaconda3/lib/python3.9/site-packages/ray/rllib/connectors/agent/pipeline.py", line 41, in __call__
    ret = c(ret)
  File "/Users/jang-yejun/opt/anaconda3/lib/python3.9/site-packages/ray/rllib/connectors/connector.py", line 265, in __call__
    return [self.transform(d) for d in acd_list]
  File "/Users/jang-yejun/opt/anaconda3/lib/python3.9/site-packages/ray/rllib/connectors/connector.py", line 265, in <listcomp>
    return [self.transform(d) for d in acd_list]
  File "/Users/jang-yejun/opt/anaconda3/lib/python3.9/site-packages/ray/rllib/connectors/agent/obs_preproc.py", line 58, in transform
    d[SampleBatch.NEXT_OBS] = self._preprocessor.transform(
  File "/Users/jang-yejun/opt/anaconda3/lib/python3.9/site-packages/ray/rllib/models/preprocessors.py", line 206, in transform
    self.check_shape(observation)
  File "/Users/jang-yejun/opt/anaconda3/lib/python3.9/site-packages/ray/rllib/models/preprocessors.py", line 74, in check_shape
    raise ValueError(
ValueError: Observation ([1.        2.014462  1.9489651 2.014462  1.        1.8034707 1.9489651
 1.8034707 1.       ] dtype=float32) outside given space (Box(0.0, 2.0, (9,), float32))!
