Failure # 1 (occurred at 2023-11-16_16-53-39)
The actor died because of an error raised in its creation task, [36mray::PPO.__init__()[39m (pid=23160, ip=127.0.0.1, actor_id=2c230bedbe02a0afb1994f2a01000000, repr=PPO)
  File "/Users/jang-yejun/opt/anaconda3/lib/python3.9/site-packages/ray/rllib/evaluation/worker_set.py", line 227, in _setup
    self.add_workers(
  File "/Users/jang-yejun/opt/anaconda3/lib/python3.9/site-packages/ray/rllib/evaluation/worker_set.py", line 593, in add_workers
    raise result.get()
  File "/Users/jang-yejun/opt/anaconda3/lib/python3.9/site-packages/ray/rllib/utils/actor_manager.py", line 481, in __fetch_result
    result = ray.get(r)
ray.exceptions.RayActorError: The actor died because of an error raised in its creation task, [36mray::RolloutWorker.__init__()[39m (pid=23176, ip=127.0.0.1, actor_id=4534a3e7f02e2870bb5d508701000000, repr=<ray.rllib.evaluation.rollout_worker.RolloutWorker object at 0x7fd72097df10>)
  File "/Users/jang-yejun/opt/anaconda3/lib/python3.9/site-packages/ray/rllib/evaluation/rollout_worker.py", line 397, in __init__
    self.env = env_creator(copy.deepcopy(self.env_context))
  File "/Users/jang-yejun/Projects/VSCodeProjects/SOUL_project/Source/RLlibPractice/RLlibpractice_politics_env.py", line 31, in <lambda>
    register_env(env_name, lambda config: ParallelPettingZooEnv(env_creator(config)))
  File "/Users/jang-yejun/opt/anaconda3/lib/python3.9/site-packages/ray/rllib/env/wrappers/pettingzoo_env.py", line 155, in __init__
    self.par_env.reset()
  File "/Users/jang-yejun/opt/anaconda3/lib/python3.9/site-packages/supersuit/generic_wrappers/utils/shared_wrapper_util.py", line 119, in reset
    observations = {
  File "/Users/jang-yejun/opt/anaconda3/lib/python3.9/site-packages/supersuit/generic_wrappers/utils/shared_wrapper_util.py", line 120, in <dictcomp>
    agent: self.modifiers[agent].modify_obs(obs)
  File "/Users/jang-yejun/opt/anaconda3/lib/python3.9/site-packages/supersuit/generic_wrappers/frame_stack.py", line 35, in modify_obs
    self.stack = stack_obs(
  File "/Users/jang-yejun/opt/anaconda3/lib/python3.9/site-packages/supersuit/utils/frame_stack.py", line 98, in stack_obs
    agent_fs[:, :, :-1] = agent_fs[:, :, 1:]
IndexError: too many indices for array: array is 1-dimensional, but 3 were indexed

During handling of the above exception, another exception occurred:

[36mray::PPO.__init__()[39m (pid=23160, ip=127.0.0.1, actor_id=2c230bedbe02a0afb1994f2a01000000, repr=PPO)
  File "/Users/jang-yejun/opt/anaconda3/lib/python3.9/site-packages/ray/rllib/algorithms/algorithm.py", line 517, in __init__
    super().__init__(
  File "/Users/jang-yejun/opt/anaconda3/lib/python3.9/site-packages/ray/tune/trainable/trainable.py", line 161, in __init__
    self.setup(copy.deepcopy(self.config))
  File "/Users/jang-yejun/opt/anaconda3/lib/python3.9/site-packages/ray/rllib/algorithms/algorithm.py", line 639, in setup
    self.workers = WorkerSet(
  File "/Users/jang-yejun/opt/anaconda3/lib/python3.9/site-packages/ray/rllib/evaluation/worker_set.py", line 179, in __init__
    raise e.args[0].args[2]
IndexError: too many indices for array: array is 1-dimensional, but 3 were indexed
