Failure # 1 (occurred at 2023-11-16_18-49-47)
[36mray::PPO.train()[39m (pid=32082, ip=127.0.0.1, actor_id=156e235b8a14f846892ef1ea01000000, repr=PPO)
           ^^^^^^^^^^^^^^^^^^^^^^^^^^^^^^^^^^^^
           ^^^^^^^^^^^^^^^^^^^^^^^^^^^^^^^
  File "/opt/homebrew/lib/python3.11/site-packages/ray/tune/trainable/trainable.py", line 342, in train
    raise skipped from exception_cause(skipped)
  File "/opt/homebrew/lib/python3.11/site-packages/ray/tune/trainable/trainable.py", line 339, in train
    result = self.step()
             ^^^^^^^^^^^
           ^^^^^^^^^^^^^^^^^^^^^^^^^^^^^^^
  File "/opt/homebrew/lib/python3.11/site-packages/ray/rllib/algorithms/algorithm.py", line 853, in step
    results, train_iter_ctx = self._run_one_training_iteration()
                              ^^^^^^^^^^^^^^^^^^^^^^^^^^^^^^^^^^
           ^^^^^^^^^^^^^^^^^^^^^^^^^^^^^^^
  File "/opt/homebrew/lib/python3.11/site-packages/ray/rllib/algorithms/algorithm.py", line 2854, in _run_one_training_iteration
    results = self.training_step()
              ^^^^^^^^^^^^^^^^^^^^
           ^^^^^^^^^^^^^^^^^^^^^^^^^^^^^^^
  File "/opt/homebrew/lib/python3.11/site-packages/ray/rllib/algorithms/ppo/ppo.py", line 429, in training_step
    train_batch = synchronous_parallel_sample(
                  ^^^^^^^^^^^^^^^^^^^^^^^^^^^^
  File "/opt/homebrew/lib/python3.11/site-packages/ray/rllib/execution/rollout_ops.py", line 85, in synchronous_parallel_sample
    sample_batches = worker_set.foreach_worker(
                     ^^^^^^^^^^^^^^^^^^^^^^^^^^
  File "/opt/homebrew/lib/python3.11/site-packages/ray/rllib/evaluation/worker_set.py", line 680, in foreach_worker
    handle_remote_call_result_errors(remote_results, self._ignore_worker_failures)
  File "/opt/homebrew/lib/python3.11/site-packages/ray/rllib/evaluation/worker_set.py", line 76, in handle_remote_call_result_errors
    raise r.get()
ray.exceptions.RayTaskError(ValueError): [36mray::RolloutWorker.apply()[39m (pid=32092, ip=127.0.0.1, actor_id=c7796c65e434939a5428026401000000, repr=<ray.rllib.evaluation.rollout_worker.RolloutWorker object at 0x13f09d9d0>)
           ^^^^^^^^^^^^^^^^^^^^^^^^^^^^^^^^^^^^
           ^^^^^^^^^^^^^^^^^^^^^^^^^^^^^^^
  File "/opt/homebrew/lib/python3.11/site-packages/ray/rllib/utils/actor_manager.py", line 185, in apply
    raise e
  File "/opt/homebrew/lib/python3.11/site-packages/ray/rllib/utils/actor_manager.py", line 176, in apply
    return func(self, *args, **kwargs)
           ^^^^^^^^^^^^^^^^^^^^^^^^^^^
  File "/opt/homebrew/lib/python3.11/site-packages/ray/rllib/execution/rollout_ops.py", line 86, in <lambda>
    lambda w: w.sample(), local_worker=False, healthy_only=True
              ^^^^^^^^^^
           ^^^^^^^^^^^^^^^^^^^^^^^^^^^^^^^
  File "/opt/homebrew/lib/python3.11/site-packages/ray/rllib/evaluation/rollout_worker.py", line 696, in sample
    batches = [self.input_reader.next()]
               ^^^^^^^^^^^^^^^^^^^^^^^^
  File "/opt/homebrew/lib/python3.11/site-packages/ray/rllib/evaluation/sampler.py", line 92, in next
    batches = [self.get_data()]
               ^^^^^^^^^^^^^^^
  File "/opt/homebrew/lib/python3.11/site-packages/ray/rllib/evaluation/sampler.py", line 277, in get_data
    item = next(self._env_runner)
           ^^^^^^^^^^^^^^^^^^^^^^
  File "/opt/homebrew/lib/python3.11/site-packages/ray/rllib/evaluation/env_runner_v2.py", line 344, in run
    outputs = self.step()
              ^^^^^^^^^^^
  File "/opt/homebrew/lib/python3.11/site-packages/ray/rllib/evaluation/env_runner_v2.py", line 370, in step
    active_envs, to_eval, outputs = self._process_observations(
                                    ^^^^^^^^^^^^^^^^^^^^^^^^^^^
  File "/opt/homebrew/lib/python3.11/site-packages/ray/rllib/evaluation/env_runner_v2.py", line 637, in _process_observations
    processed = policy.agent_connectors(acd_list)
                ^^^^^^^^^^^^^^^^^^^^^^^^^^^^^^^^^
  File "/opt/homebrew/lib/python3.11/site-packages/ray/rllib/connectors/agent/pipeline.py", line 41, in __call__
    ret = c(ret)
          ^^^^^^
  File "/opt/homebrew/lib/python3.11/site-packages/ray/rllib/connectors/connector.py", line 265, in __call__
    return [self.transform(d) for d in acd_list]
           ^^^^^^^^^^^^^^^^^^^^^^^^^^^^^^^^^^^^^
  File "/opt/homebrew/lib/python3.11/site-packages/ray/rllib/connectors/connector.py", line 265, in <listcomp>
    return [self.transform(d) for d in acd_list]
            ^^^^^^^^^^^^^^^^^
  File "/opt/homebrew/lib/python3.11/site-packages/ray/rllib/connectors/agent/obs_preproc.py", line 58, in transform
    d[SampleBatch.NEXT_OBS] = self._preprocessor.transform(
                              ^^^^^^^^^^^^^^^^^^^^^^^^^^^^^
  File "/opt/homebrew/lib/python3.11/site-packages/ray/rllib/models/preprocessors.py", line 206, in transform
    self.check_shape(observation)
  File "/opt/homebrew/lib/python3.11/site-packages/r", line 74, in check_shape
    raise ValueError(
ValueError: Observation ([0. 0. 0. 0. 0. 0. 0. 0. 0. 0. 0. 0. 0. 0. 0. 0. 0. 0. 1. 0. 0. 0. 1. 0.
 0. 0. 1.] dtype=float32) outside given space (Box(0.0, 2.0, (9,), float32))!
